Workbook
Name Analysis_Period: 'Property Summary'!$D$8
Name Analysis_Start: 'Property Summary'!$D$7
Name Basis: 'Property Summary'!$H$6
Name Cap_Year: 'Property Summary'!$D$9
Name CashFlow_Table: Debt!$C$4:$R$7
Name Debt: 'Property Summary'!$H$18
Name Debt_Table2: Debt!$B$4:$R$7
Name Discount_Rate: 'Property Summary'!$D$12
Name Equity_Share_LP: 'Investor Returns'!$C$9
Name Equity_Share_LP: #REF!
Name Equity_Share_Sponsor: 'Investor Returns'!$C$8
Name Equity_Share_Sponsor: #REF!
Name Exit_Cap_Yr_1: 'Property Summary'!$D$11
Name GP_Only?: 'Investor Returns'!$E$8
Name Initial_Equity: 'Property Summary'!$H$22
Name Name: 'Property Summary'!$D$3
Name P_List_Table: 'Property Assumptions'!$B$4:$W$5
Name P_List_Table_2: 'Property Assumptions'!$C$5:$W$5
Name Preferred_Return: 'Investor Returns'!$E$14
Name Preferred_Return: #REF!
Name Promote_Structure: 'Investor Returns'!$B$13:$I$17
Name Promote_Structure: #REF!
Name Property_List: OFFSET('Property Assumptions'!$C$5,0,0,COUNTA('Property Assumptions'!$C:$C)-1,1)
Name Property_Number_List: 'Property Assumptions'!$B$5:$B$5
Name Purchase_Price: 'Property Summary'!$D$18
Name Total_Equity: 'Investor Returns'!$D$10
Name Units: 'Property Summary'!$H$3

Sheet Version
B2: Apartment Acquisition Model (Original)
B3: Model Resources | K3: =B16 -> v2.4
B4: Author: Spencer Burton | G4: Important Links:
B5: https://www.adventuresincre.com/ | G5: Visit this Model's Webpage
G6: Guides and Tutorials for Using the Model
B7: Compatibility
B8: Excel 2013 | G8: Browse our entire Library of Real Estate Models
B9: Excel 2016 | G9: Download Our New Apartment Acquisition Model (Compatible with Mac)
B10: Excel 365
B11: NOT COMPATIBLE WITH MAC
B13: AdventuresinCRE.com and its affiliates do not provide tax, legal, investment, or accounting advice. This material has been prepared for informational purposes only, and is not intended to provide, and should not be relied on for, tax, legal or accounting advice. You should consult your own tax, legal and accounting advisors before engaging in any transaction. This model may contains errors. Verify all calculations being using this model to make investment decisions.
B14: LEARN TO BUILD INSTITUTIONAL-QUALITY REAL ESTATE MODELS FROM SCRATCH - CLICK HERE TO LEARN MORE -
B15: Changelog | H15: Disclaimer: This model may contain errors
B16: v2.4
B17: Updated the Loan Balance formula (Row 7 - Debt tab) to reflect monthly payments instead of annual, ensuring alignment with the amortization structure
B19: v2.3
B20: Improved Sponsor Distribution formula on Investor Returns tab to make it easier to audit
B21: Added option to toggle between SF and M2 (cell H2 on the Property Summary tab)
B22: Misc. formatting enhancements
B24: v2.2
B25: Added new Versions tab
B26: Fixed 'Capitalization' box on Property Summary tab; now properly links to Investor Returns tab
B27: Updated default 'Purchase Price Method' to 'Manual Input' on Property Summary tab
B28: Updated default 'Loan Amount' to include formula linked to 'Purchase Price'
B29: Moved LTV and LTC metrics immediately below 'Loan Amount' input
... B59: Added a few ratios to the Annual Cash Flow tab

Sheet Property Summary
B2: Property Summary | H2: SF
B3: Property Name | D3: Serrano Village | F3: Apartment Units | H3: 124 | J3: Capitalization | K3: % | L3: Amount
B4: City, State | D4: Phoenix, AZ | F4: Upfront CapEx | H4: 0 | J4: Sponsor | K4: =+'Investor Returns'!Equity_Share_Sponsor -> 0.1 | L4: =+'Investor Returns'!D8 -> 300360.13
B5: Current Occupancy | D5: 0.93 | F5: Acquisition Cost | H5: 0.01 | J5: LP Investors | K5: =1-K4 -> 0.9 | L5: =+'Investor Returns'!D9 -> 2703241.2
B6: Purchase Price Method | D6: Manual Input | F6: All-in-Basis | H6: =((1+H5)*Purchase_Price)+(Debt*H29)+H4 -> 7369625 | J6: [See Investor Returns tab for assumptions]
B7: Analysis Start | D7: 42370 | F7: Going-In Cap Rate | H7: =H9/D18 -> 0.060253588
B8: Analysis Period | D8: 10 | F8: Price/Unit | H8: =Purchase_Price/Units -> 58467.742
B9: Terminal Cap Year | D9: =MIN(Analysis_Period+1,15) -> 11 | F9: Year 1 NOI | H9: ='Property Returns'!D7 -> 436838.51
B10: Terminal Cap Rate Growth/Yr | D10: 0 | F10: Year 3 NOI | H10: ='Property Returns'!F7 -> 581601.71
B11: Market Cap Rate (Yr. 1) | D11: 0.065 | F11: ="Terminal Cap Rate (Yr. "&Analysis_Period&")" -> Terminal Cap Rate (Yr. 10) | H11: =H7+(Analysis_Period*(D10/10000)) -> 0.060253588
B12: Discount Rate | D12: 0.075 | F12: Terminal Value | H12: =HLOOKUP(Analysis_Period,'Property Returns'!$D$3:$S$32,10,FALSE) -> 9639357.4
B13: Replacement Cost (per unit) | D13: 60000
B14: Set Purchase Price | D14: 7250000 | F14: Other Income/Year | H14: 25000
F15: General Vacancy | H15: 0.08
B17: Property Metrics | F17: Financing Assumptions | J17: Inflation
B18: Purchase Price | D18: =IF(D6="Manual Input",D14,IF(D6="Present Value",D19,IF(D6="Cap Year 1 NOI",H9/Exit_Cap_Yr_1,D20))) -> 7250000 | F18: Loan Amount | H18: =D14*0.65 -> 4712500 | J18: Rent | L18: 0.015
B19: ="Present Value @ "&TEXT(Discount_Rate,"0.00%") -> Present Value @ 7.50% | D19: =NPV(Discount_Rate,'Property Returns'!$D$18:$R$18) -> 7323615.9 | F19: LTV | H19: =Debt/D19 -> 0.6434663 | J19: Other Income | L19: 0.01
B20: ="Replacement Cost @ "&D13/1000&"k/unit" -> Replacement Cost @ 60k/unit | D20: ='Property Summary'!D13*Units -> 7440000 | F20: LTC | H20: =Debt/Basis -> 0.63944909 | J20: Operating Expenses | L20: 0.02
F21: Lender Fees ($) | H21: =Debt*'Property Summary'!H29 -> 47125 | J21: Capital Expenditures | L21: 0.02
B22: Unlevered IRR | D22: =HLOOKUP(Analysis_Period,'Property Returns'!$D$3:$T$39,18,FALSE) -> 0.074209224 | F22: Initial Equity Required | H22: =Basis-Debt -> 2657125 | J22: Releasing Costs | L22: 0.02
B23: Unlevered Equity Multiple | D23: =HLOOKUP(Analysis_Period,'Property Returns'!$D$3:$T$39,19,FALSE) -> 1.8657632 | F23: Total Equity Required | H23: =Total_Equity -> 3003601.3
B24: Avg. Free and Clear Return | D24: =HLOOKUP(Analysis_Period,'Property Returns'!$D$3:$T$39,15,FALSE) -> 0.055777839
F25: Interest Rate | H25: 0.0425
B26: Levered IRR | D26: =HLOOKUP(Analysis_Period,'Property Returns'!$D$3:$T$39,36,FALSE) -> 0.10915008 | F26: Years I/O | H26: 0
B27: Levered Equity Multiple | D27: =HLOOKUP(Analysis_Period,'Property Returns'!$D$3:$T$39,37,FALSE) -> 2.5205638 | F27: Amo. Period | H27: 30
B28: Avg. Cash-on-Cash Return | D28: =HLOOKUP(Analysis_Period,'Property Returns'!$D$3:$T$39,34,FALSE) -> 0.050005081 | F28: Term | H28: 10
F29: Lender Fees (%) | H29: 0.01
B30: Min. DSCR (NOI) | D30: =MIN('Property Returns'!$D$27:$R$27) -> 1.570277
B31: Min. Debt Yield (NOI) | D31: =MIN('Property Returns'!$D$28:$R$28) -> 0.094287387
B33: Investor Returns | D33: Sponsor | F33: Limited Partner(s)
B34: IRR | D34: ='Investor Returns'!D32 -> 0.14827582 | F34: ='Investor Returns'!D24 -> 0.10388158
B35: Total Distributions | D35: ='Investor Returns'!D28 -> 1061225.1 | F35: ='Investor Returns'!D21 -> 6509543.7
B36: Total Contributions | D36: ='Investor Returns'!D30 -> 300360.13 | F36: ='Investor Returns'!D22 -> 2703241.2
B37: Total Profit | D37: ='Investor Returns'!D31 -> 760864.94 | F37: ='Investor Returns'!D23 -> 3806302.5
B38: Equity Multiple | D38: ='Investor Returns'!D33 -> 3.5331756 | F38: ='Investor Returns'!D25 -> 2.4080514

Sheet Property Assumptions
C2: Property Assumptions
B3: Property Assumptions | G3: Property Valuation | L3: Financing Assumptions
B4: # | C4: Property Name | D4: City, State | E4: NRA | F4: Occ. % | G4: Price | H4: Cap Rate | I4: PSF | J4: Equity Req'd | K4: Acquisition Cost % | L4: Interest Rate | M4: Amo Payment | N4: I/O Payment | O4: Initial Loan Balance | P4: Years I/O | Q4: Amo Period | R4: Term | S4: LTV | T4: Unlevered All-In Basis | U4: Upfront CapEx | W4: Lender Fees %
B5: 1 | C5: =Name -> Serrano Village | D5: ='Property Summary'!D4 -> Phoenix, AZ | E5: ='Property Summary'!D5 -> 0.93 | F5: ='Property Summary'!#REF! -> #REF! | G5: 15000000 | H5: ='Property Returns'!D7/Purchase_Price -> 0.060253588 | I5: =IF(G5="","",G5/'Property Summary'!D5) -> 16129032 | J5: =IF(B5="","",T5-O5+(O5*W5)) -> 10484625 | K5: ='Property Summary'!H5 -> 0.01 | L5: ='Property Summary'!H25 -> 0.0425 | M5: =IF(B5="","",-PMT(L5/12,(Q5-P5)*12,O5)*12) -> 278192.01 | N5: =IF(B5="","",O5*L5) -> 200281.25 | O5: =Debt -> 4712500 | P5: ='Property Summary'!H26 -> 0 | Q5: ='Property Summary'!H27 -> 30 | R5: ='Property Summary'!H28 -> 10 | S5: ='Property Summary'!H19 -> 0.6434663 | T5: =IF(B5="","",G5+(G5*K5)+U5) -> 15150000 | U5: ='Property Summary'!H4 -> 0 | W5: ='Property Summary'!H29 -> 0.01

Sheet MF Rent Roll
B2: Multifamily Rent Roll | G2: Residential Units | J2: =Units -> 124 | K2: =J2-SUM($C$5:$C$38) -> 0 | L2: Units Remaining
P3: Blended
B4: Unit Name | C4: # of Units | D4: Beds | E4: Baths | F4: ="Rentable Area ("&'Property Summary'!H2&")" -> Rentable Area (SF) | G4: In-Place Rent/Mo. | H4: Market Rent/Mo | I4: Month to Roll to Market | J4: Lease Term | K4: CapEx /Unit/Mo. | L4: Free Rent Per Lease | M4: Days Vacant Between Leases | N4: Releasing Cost per Unit | O4: Renewal Probability | P4: Free Rent | Q4: Days Vacant | R4: Releasing Cost
B5: Studio | C5: 40 | D5: 0 | E5: 1 | F5: 430 | G5: 510 | H5: 630 | I5: 13 | J5: 12 | K5: 50 | L5: 0 | M5: 20 | N5: 300 | O5: 0.6 | P5: =IF(B5="","",(1-O5)*L5) -> 0 | Q5: =IF(B5="","",(1-O5)*M5) -> 8 | R5: =IF(B5="","",(1-O5)*N5) -> 120
B6: 1bd/1ba | C6: 24 | D6: 1 | E6: 1 | F6: 671 | G6: 660 | H6: 780 | I6: 16 | J6: 12 | K6: 50 | L6: 0 | M6: 20 | N6: 300 | O6: 0.6 | P6: =IF(B6="","",(1-O6)*L6) -> 0 | Q6: =IF(B6="","",(1-O6)*M6) -> 8 | R6: =IF(B6="","",(1-O6)*N6) -> 120
B7: 2bd/2ba | C7: 24 | D7: 2 | E7: 2 | F7: 945 | G7: 850 | H7: 970 | I7: 19 | J7: 12 | K7: 60 | L7: 0 | M7: 25 | N7: 350 | O7: 0.6 | P7: =IF(B7="","",(1-O7)*L7) -> 0 | Q7: =IF(B7="","",(1-O7)*M7) -> 10 | R7: =IF(B7="","",(1-O7)*N7) -> 140
B8: 2bd/1.5ba | C8: 12 | D8: 2 | E8: 1.5 | F8: 1025 | G8: 850 | H8: 970 | I8: 22 | J8: 12 | K8: 65 | L8: 0 | M8: 25 | N8: 350 | O8: 0.6 | P8: =IF(B8="","",(1-O8)*L8) -> 0 | Q8: =IF(B8="","",(1-O8)*M8) -> 10 | R8: =IF(B8="","",(1-O8)*N8) -> 140
B9: 3bd/2ba | C9: 24 | D9: 3 | E9: 2 | F9: 1046 | G9: 1100 | H9: 1220 | I9: 25 | J9: 12 | K9: 70 | L9: 0 | M9: 30 | N9: 400 | O9: 0.6 | P9: =IF(B9="","",(1-O9)*L9) -> 0 | Q9: =IF(B9="","",(1-O9)*M9) -> 12 | R9: =IF(B9="","",(1-O9)*N9) -> 160
P10: =IF(B10="","",(1-O10)*L10) | Q10: =IF(B10="","",(1-O10)*M10) | R10: =IF(B10="","",(1-O10)*N10)
P11: =IF(B11="","",(1-O11)*L11) | Q11: =IF(B11="","",(1-O11)*M11) | R11: =IF(B11="","",(1-O11)*N11)
P12: =IF(B12="","",(1-O12)*L12) | Q12: =IF(B12="","",(1-O12)*M12) | R12: =IF(B12="","",(1-O12)*N12)
P13: =IF(B13="","",(1-O13)*L13) | Q13: =IF(B13="","",(1-O13)*M13) | R13: =IF(B13="","",(1-O13)*N13)
P14: =IF(B14="","",(1-O14)*L14) | Q14: =IF(B14="","",(1-O14)*M14) | R14: =IF(B14="","",(1-O14)*N14)
P15: =IF(B15="","",(1-O15)*L15) | Q15: =IF(B15="","",(1-O15)*M15) | R15: =IF(B15="","",(1-O15)*N15)
P16: =IF(B16="","",(1-O16)*L16) | Q16: =IF(B16="","",(1-O16)*M16) | R16: =IF(B16="","",(1-O16)*N16)
P17: =IF(B17="","",(1-O17)*L17) | Q17: =IF(B17="","",(1-O17)*M17) | R17: =IF(B17="","",(1-O17)*N17)
P18: =IF(B18="","",(1-O18)*L18) | Q18: =IF(B18="","",(1-O18)*M18) | R18: =IF(B18="","",(1-O18)*N18)
P19: =IF(B19="","",(1-O19)*L19) | Q19: =IF(B19="","",(1-O19)*M19) | R19: =IF(B19="","",(1-O19)*N19)
P20: =IF(B20="","",(1-O20)*L20) | Q20: =IF(B20="","",(1-O20)*M20) | R20: =IF(B20="","",(1-O20)*N20)
P21: =IF(B21="","",(1-O21)*L21) | Q21: =IF(B21="","",(1-O21)*M21) | R21: =IF(B21="","",(1-O21)*N21)
... P38: =IF(B38="","",(1-O38)*L38) | Q38: =IF(B38="","",(1-O38)*M38) | R38: =IF(B38="","",(1-O38)*N38)

Sheet Expenses
B2: Operating Expense Assumptions
F4: Stabilized
B5: Growth Rate | E5: Year 1 per Unit | F5: ='Property Returns'!D3 -> 1 | G5: ='Property Returns'!E3 -> 2 | H5: ='Property Returns'!F3 -> 3 | I5: ='Property Returns'!G3 -> 4 | J5: ='Property Returns'!H3 -> 5 | K5: ='Property Returns'!I3 -> 6 | L5: ='Property Returns'!J3 -> 7 | M5: ='Property Returns'!K3 -> 8 | ... U5: ='Property Returns'!S3
B6: ='Property Summary'!$L$20 -> 0.02 | C6: - Marketing | E6: =F6/Units -> -200 | F6: -24800 | G6: =IF(G$5="","",-ABS((F6*(1+$B6)))) -> -25296 | H6: =IF(H$5="","",-ABS((G6*(1+$B6)))) -> -25801.92 | I6: =IF(I$5="","",-ABS((H6*(1+$B6)))) -> -26317.958 | J6: =IF(J$5="","",-ABS((I6*(1+$B6)))) -> -26844.318 | K6: =IF(K$5="","",-ABS((J6*(1+$B6)))) -> -27381.204 | L6: =IF(L$5="","",-ABS((K6*(1+$B6)))) -> -27928.828 | M6: =IF(M$5="","",-ABS((L6*(1+$B6)))) -> -28487.405 | N6: =IF(N$5="","",-ABS((M6*(1+$B6)))) -> -29057.153 | ... U6: =IF(U$5="","",-ABS((T6*(1+$B6))))
B7: ='Property Summary'!$L$20 -> 0.02 | C7: - Administrative | E7: =F7/Units -> -250 | F7: -31000 | G7: =IF(G$5="","",-ABS((F7*(1+$B7)))) -> -31620 | H7: =IF(H$5="","",-ABS((G7*(1+$B7)))) -> -32252.4 | I7: =IF(I$5="","",-ABS((H7*(1+$B7)))) -> -32897.448 | J7: =IF(J$5="","",-ABS((I7*(1+$B7)))) -> -33555.397 | K7: =IF(K$5="","",-ABS((J7*(1+$B7)))) -> -34226.505 | L7: =IF(L$5="","",-ABS((K7*(1+$B7)))) -> -34911.035 | M7: =IF(M$5="","",-ABS((L7*(1+$B7)))) -> -35609.256 | N7: =IF(N$5="","",-ABS((M7*(1+$B7)))) -> -36321.441 | ... U7: =IF(U$5="","",-ABS((T7*(1+$B7))))
B8: ='Property Summary'!$L$20 -> 0.02 | C8: - Utilities | E8: =F8/Units -> -800 | F8: -99200 | G8: =IF(G$5="","",-ABS((F8*(1+$B8)))) -> -101184 | H8: =IF(H$5="","",-ABS((G8*(1+$B8)))) -> -103207.68 | I8: =IF(I$5="","",-ABS((H8*(1+$B8)))) -> -105271.83 | J8: =IF(J$5="","",-ABS((I8*(1+$B8)))) -> -107377.27 | K8: =IF(K$5="","",-ABS((J8*(1+$B8)))) -> -109524.82 | L8: =IF(L$5="","",-ABS((K8*(1+$B8)))) -> -111715.31 | M8: =IF(M$5="","",-ABS((L8*(1+$B8)))) -> -113949.62 | N8: =IF(N$5="","",-ABS((M8*(1+$B8)))) -> -116228.61 | ... U8: =IF(U$5="","",-ABS((T8*(1+$B8))))
B9: ='Property Summary'!$L$20 -> 0.02 | C9: - Payroll | E9: =F9/Units -> -1200 | F9: -148800 | G9: =IF(G$5="","",-ABS((F9*(1+$B9)))) -> -151776 | H9: =IF(H$5="","",-ABS((G9*(1+$B9)))) -> -154811.52 | I9: =IF(I$5="","",-ABS((H9*(1+$B9)))) -> -157907.75 | J9: =IF(J$5="","",-ABS((I9*(1+$B9)))) -> -161065.91 | K9: =IF(K$5="","",-ABS((J9*(1+$B9)))) -> -164287.22 | L9: =IF(L$5="","",-ABS((K9*(1+$B9)))) -> -167572.97 | M9: =IF(M$5="","",-ABS((L9*(1+$B9)))) -> -170924.43 | N9: =IF(N$5="","",-ABS((M9*(1+$B9)))) -> -174342.92 | ... U9: =IF(U$5="","",-ABS((T9*(1+$B9))))
B10: ='Property Summary'!$L$20 -> 0.02 | C10: -Repair and maintenance | E10: =F10/Units -> -700 | F10: -86800 | G10: =IF(G$5="","",-ABS((F10*(1+$B10)))) -> -88536 | H10: =IF(H$5="","",-ABS((G10*(1+$B10)))) -> -90306.72 | I10: =IF(I$5="","",-ABS((H10*(1+$B10)))) -> -92112.854 | J10: =IF(J$5="","",-ABS((I10*(1+$B10)))) -> -93955.111 | K10: =IF(K$5="","",-ABS((J10*(1+$B10)))) -> -95834.214 | L10: =IF(L$5="","",-ABS((K10*(1+$B10)))) -> -97750.898 | M10: =IF(M$5="","",-ABS((L10*(1+$B10)))) -> -99705.916 | N10: =IF(N$5="","",-ABS((M10*(1+$B10)))) -> -101700.03 | ... U10: =IF(U$5="","",-ABS((T10*(1+$B10))))
C11: - Mgmt (% of EGR) | D11: 0.03 | E11: =F11/Units -> -255.08942 | F11: =IF(F5="","",-$D11*'Annual Cash Flow'!E12) -> -31631.088 | G11: =IF(G5="","",-$D11*'Annual Cash Flow'!F12) -> -34320.075 | H11: =IF(H5="","",-$D11*'Annual Cash Flow'!G12) -> -36840.373 | I11: =IF(I5="","",-$D11*'Annual Cash Flow'!H12) -> -37389.153 | J11: =IF(J5="","",-$D11*'Annual Cash Flow'!I12) -> -37946.127 | K11: =IF(K5="","",-$D11*'Annual Cash Flow'!J12) -> -38511.417 | L11: =IF(L5="","",-$D11*'Annual Cash Flow'!K12) -> -39085.147 | M11: =IF(M5="","",-$D11*'Annual Cash Flow'!L12) -> -39667.443 | ... U11: =IF(U5="","",-$D11*'Annual Cash Flow'!T12)
B12: ='Property Summary'!$L$20 -> 0.02 | C12: -Insurance | E12: =F12/Units -> -225 | F12: -27900 | G12: =IF(G$5="","",-ABS((F12*(1+$B12)))) -> -28458 | H12: =IF(H$5="","",-ABS((G12*(1+$B12)))) -> -29027.16 | I12: =IF(I$5="","",-ABS((H12*(1+$B12)))) -> -29607.703 | J12: =IF(J$5="","",-ABS((I12*(1+$B12)))) -> -30199.857 | K12: =IF(K$5="","",-ABS((J12*(1+$B12)))) -> -30803.854 | L12: =IF(L$5="","",-ABS((K12*(1+$B12)))) -> -31419.931 | M12: =IF(M$5="","",-ABS((L12*(1+$B12)))) -> -32048.33 | N12: =IF(N$5="","",-ABS((M12*(1+$B12)))) -> -32689.297 | ... U12: =IF(U$5="","",-ABS((T12*(1+$B12))))
B13: ='Property Summary'!$L$20 -> 0.02 | C13: -Taxes | E13: =F13/Units -> -1350 | F13: -167400 | G13: =IF(G$5="","",-ABS((F13*(1+$B13)))) -> -170748 | H13: =IF(H$5="","",-ABS((G13*(1+$B13)))) -> -174162.96 | I13: =IF(I$5="","",-ABS((H13*(1+$B13)))) -> -177646.22 | J13: =IF(J$5="","",-ABS((I13*(1+$B13)))) -> -181199.14 | K13: =IF(K$5="","",-ABS((J13*(1+$B13)))) -> -184823.13 | L13: =IF(L$5="","",-ABS((K13*(1+$B13)))) -> -188519.59 | M13: =IF(M$5="","",-ABS((L13*(1+$B13)))) -> -192289.98 | N13: =IF(N$5="","",-ABS((M13*(1+$B13)))) -> -196135.78 | ... U13: =IF(U$5="","",-ABS((T13*(1+$B13))))
B14: =RATE(Analysis_Period-1,,-F14,LOOKUP(Analysis_Period,$F$5:$U$5,F14:U14)) -> 0.020468465 | C14: Operating Expenses | E14: =-F14/Units -> 4980.0894 | F14: =IF(F5="","",-ABS(F6)-ABS(F7)-ABS(F8)-ABS(F9)-ABS(F10)+F11-ABS(F12)-ABS(F13)) -> -617531.09 | G14: =IF(G5="","",-ABS(G6)-ABS(G7)-ABS(G8)-ABS(G9)-ABS(G10)+G11-ABS(G12)-ABS(G13)) -> -631938.07 | H14: =IF(H5="","",-ABS(H6)-ABS(H7)-ABS(H8)-ABS(H9)-ABS(H10)+H11-ABS(H12)-ABS(H13)) -> -646410.73 | I14: =IF(I5="","",-ABS(I6)-ABS(I7)-ABS(I8)-ABS(I9)-ABS(I10)+I11-ABS(I12)-ABS(I13)) -> -659150.92 | J14: =IF(J5="","",-ABS(J6)-ABS(J7)-ABS(J8)-ABS(J9)-ABS(J10)+J11-ABS(J12)-ABS(J13)) -> -672143.13 | K14: =IF(K5="","",-ABS(K6)-ABS(K7)-ABS(K8)-ABS(K9)-ABS(K10)+K11-ABS(K12)-ABS(K13)) -> -685392.36 | L14: =IF(L5="","",-ABS(L6)-ABS(L7)-ABS(L8)-ABS(L9)-ABS(L10)+L11-ABS(L12)-ABS(L13)) -> -698903.71 | M14: =IF(M5="","",-ABS(M6)-ABS(M7)-ABS(M8)-ABS(M9)-ABS(M10)+M11-ABS(M12)-ABS(M13)) -> -712682.38 | ... U14: =IF(U5="","",-ABS(U6)-ABS(U7)-ABS(U8)-ABS(U9)-ABS(U10)+U11-ABS(U12)-ABS(U13))
F18: =F5 -> 1 | G18: =G5 -> 2 | H18: =H5 -> 3 | I18: =I5 -> 4 | J18: =J5 -> 5 | K18: =K5 -> 6 | L18: =L5 -> 7 | M18: =M5 -> 8 | ... U18: =U5
B19: Property Renovation/Improvement Costs | F19: 350000 | G19: 200000 | H19: 0 | I19: 0 | J19: 0 | K19: 0 | L19: 0 | M19: 0 | N19: 0 | O19: 0 | P19: 0
B20: Total | F20: =IF(F18="","",-ABS(F19)) -> -350000 | G20: =IF(G18="","",-ABS(G19)) -> -200000 | H20: =IF(H18="","",-ABS(H19)) -> 0 | I20: =IF(I18="","",-ABS(I19)) -> 0 | J20: =IF(J18="","",-ABS(J19)) -> 0 | K20: =IF(K18="","",-ABS(K19)) -> 0 | L20: =IF(L18="","",-ABS(L19)) -> 0 | M20: =IF(M18="","",-ABS(M19)) -> 0 | ... U20: =IF(U18="","",-ABS(U19))

Sheet Annual Cash Flow
B2: Multifamily Annual Cash Flow
D5: Ratios | E5: ='Property Returns'!D3 -> 1 | F5: ='Property Returns'!E3 -> 2 | G5: ='Property Returns'!F3 -> 3 | H5: ='Property Returns'!G3 -> 4 | I5: ='Property Returns'!H3 -> 5 | J5: ='Property Returns'!I3 -> 6 | K5: ='Property Returns'!J3 -> 7 | L5: ='Property Returns'!K3 -> 8 | ... T5: ='Property Returns'!S3
B6: + Base Rent | E6: =IF(E5="","",SUMIF('MF Rents'!$U$3:$GR$3,'Annual Cash Flow'!E5,'MF Rents'!$U$40:$GR$40)) -> 1118880 | F6: =IF(F5="","",SUMIF('MF Rents'!$U$3:$GR$3,'Annual Cash Flow'!F5,'MF Rents'!$U$40:$GR$40)) -> 1242360 | G6: =IF(G5="","",SUMIF('MF Rents'!$U$3:$GR$3,'Annual Cash Flow'!G5,'MF Rents'!$U$40:$GR$40)) -> 1336655.1 | H6: =IF(H5="","",SUMIF('MF Rents'!$U$3:$GR$3,'Annual Cash Flow'!H5,'MF Rents'!$U$40:$GR$40)) -> 1356705 | I6: =IF(I5="","",SUMIF('MF Rents'!$U$3:$GR$3,'Annual Cash Flow'!I5,'MF Rents'!$U$40:$GR$40)) -> 1377055.5 | J6: =IF(J5="","",SUMIF('MF Rents'!$U$3:$GR$3,'Annual Cash Flow'!J5,'MF Rents'!$U$40:$GR$40)) -> 1397711.4 | K6: =IF(K5="","",SUMIF('MF Rents'!$U$3:$GR$3,'Annual Cash Flow'!K5,'MF Rents'!$U$40:$GR$40)) -> 1418677 | L6: =IF(L5="","",SUMIF('MF Rents'!$U$3:$GR$3,'Annual Cash Flow'!L5,'MF Rents'!$U$40:$GR$40)) -> 1439957.2 | ... T6: =IF(T5="","",SUMIF('MF Rents'!$U$3:$GR$3,'Annual Cash Flow'!T5,'MF Rents'!$U$40:$GR$40))
B7: + Other Income | D7: =AVERAGE(E7:T7)/AVERAGE($E$8:$T$8) -> 0.018743323 | E7: =IF(E5="","",'Property Summary'!$H$14*(1+'Property Summary'!$L$19)^('Annual Cash Flow'!E5-1)) -> 25000 | F7: =IF(F5="","",'Property Summary'!$H$14*(1+'Property Summary'!$L$19)^('Annual Cash Flow'!F5-1)) -> 25250 | G7: =IF(G5="","",'Property Summary'!$H$14*(1+'Property Summary'!$L$19)^('Annual Cash Flow'!G5-1)) -> 25502.5 | H7: =IF(H5="","",'Property Summary'!$H$14*(1+'Property Summary'!$L$19)^('Annual Cash Flow'!H5-1)) -> 25757.525 | I7: =IF(I5="","",'Property Summary'!$H$14*(1+'Property Summary'!$L$19)^('Annual Cash Flow'!I5-1)) -> 26015.1 | J7: =IF(J5="","",'Property Summary'!$H$14*(1+'Property Summary'!$L$19)^('Annual Cash Flow'!J5-1)) -> 26275.251 | K7: =IF(K5="","",'Property Summary'!$H$14*(1+'Property Summary'!$L$19)^('Annual Cash Flow'!K5-1)) -> 26538.004 | L7: =IF(L5="","",'Property Summary'!$H$14*(1+'Property Summary'!$L$19)^('Annual Cash Flow'!L5-1)) -> 26803.384 | ... T7: =IF(T5="","",'Property Summary'!$H$14*(1+'Property Summary'!$L$19)^('Annual Cash Flow'!T5-1))
B8: Potential Gross Income | E8: =IF(E5="","",SUM(E6:E7)) -> 1143880 | F8: =IF(F5="","",SUM(F6:F7)) -> 1267610 | G8: =IF(G5="","",SUM(G6:G7)) -> 1362157.6 | H8: =IF(H5="","",SUM(H6:H7)) -> 1382462.5 | I8: =IF(I5="","",SUM(I6:I7)) -> 1403070.6 | J8: =IF(J5="","",SUM(J6:J7)) -> 1423986.6 | K8: =IF(K5="","",SUM(K6:K7)) -> 1445215 | L8: =IF(L5="","",SUM(L6:L7)) -> 1466760.6 | ... T8: =IF(T5="","",SUM(T6:T7))
B10: - Rent Abatement | D10: =-AVERAGE(E10:T10)/AVERAGE($E$8:$T$8) -> 0 | E10: =IF(E5="","",-SUMIF('MF Free Rent'!$S$3:$GP$3,'Annual Cash Flow'!E5,'MF Free Rent'!$S$40:$GP$40)) -> 0 | F10: =IF(F5="","",-SUMIF('MF Free Rent'!$S$3:$GP$3,'Annual Cash Flow'!F5,'MF Free Rent'!$S$40:$GP$40)) -> 0 | G10: =IF(G5="","",-SUMIF('MF Free Rent'!$S$3:$GP$3,'Annual Cash Flow'!G5,'MF Free Rent'!$S$40:$GP$40)) -> 0 | H10: =IF(H5="","",-SUMIF('MF Free Rent'!$S$3:$GP$3,'Annual Cash Flow'!H5,'MF Free Rent'!$S$40:$GP$40)) -> 0 | I10: =IF(I5="","",-SUMIF('MF Free Rent'!$S$3:$GP$3,'Annual Cash Flow'!I5,'MF Free Rent'!$S$40:$GP$40)) -> 0 | J10: =IF(J5="","",-SUMIF('MF Free Rent'!$S$3:$GP$3,'Annual Cash Flow'!J5,'MF Free Rent'!$S$40:$GP$40)) -> 0 | K10: =IF(K5="","",-SUMIF('MF Free Rent'!$S$3:$GP$3,'Annual Cash Flow'!K5,'MF Free Rent'!$S$40:$GP$40)) -> 0 | L10: =IF(L5="","",-SUMIF('MF Free Rent'!$S$3:$GP$3,'Annual Cash Flow'!L5,'MF Free Rent'!$S$40:$GP$40)) -> 0 | ... T10: =IF(T5="","",-SUMIF('MF Free Rent'!$S$3:$GP$3,'Annual Cash Flow'!T5,'MF Free Rent'!$S$40:$GP$40))
B11: - Vacancy | D11: =-AVERAGE(E11:T11)/AVERAGE($E$8:$T$8) -> 0.096931682 | E11: =IF(E5="","",-SUMIF('MF Vacancy'!$S$3:$GP$3,'Annual Cash Flow'!E5,'MF Vacancy'!$S$40:$GP$40)) -> -89510.4 | F11: =IF(F5="","",-SUMIF('MF Vacancy'!$S$3:$GP$3,'Annual Cash Flow'!F5,'MF Vacancy'!$S$40:$GP$40)) -> -123607.51 | G11: =IF(G5="","",-SUMIF('MF Vacancy'!$S$3:$GP$3,'Annual Cash Flow'!G5,'MF Vacancy'!$S$40:$GP$40)) -> -134145.19 | H11: =IF(H5="","",-SUMIF('MF Vacancy'!$S$3:$GP$3,'Annual Cash Flow'!H5,'MF Vacancy'!$S$40:$GP$40)) -> -136157.36 | I11: =IF(I5="","",-SUMIF('MF Vacancy'!$S$3:$GP$3,'Annual Cash Flow'!I5,'MF Vacancy'!$S$40:$GP$40)) -> -138199.72 | J11: =IF(J5="","",-SUMIF('MF Vacancy'!$S$3:$GP$3,'Annual Cash Flow'!J5,'MF Vacancy'!$S$40:$GP$40)) -> -140272.72 | K11: =IF(K5="","",-SUMIF('MF Vacancy'!$S$3:$GP$3,'Annual Cash Flow'!K5,'MF Vacancy'!$S$40:$GP$40)) -> -142376.81 | L11: =IF(L5="","",-SUMIF('MF Vacancy'!$S$3:$GP$3,'Annual Cash Flow'!L5,'MF Vacancy'!$S$40:$GP$40)) -> -144512.46 | ... T11: =IF(T5="","",-SUMIF('MF Vacancy'!$S$3:$GP$3,'Annual Cash Flow'!T5,'MF Vacancy'!$S$40:$GP$40))
B12: Effective Gross Revenue | D12: =AVERAGE(E12:T12)/AVERAGE($E$8:$T$8) -> 0.90306832 | E12: =IF(E5="","",SUM(E8:E11)) -> 1054369.6 | F12: =IF(F5="","",SUM(F8:F11)) -> 1144002.5 | G12: =IF(G5="","",SUM(G8:G11)) -> 1228012.4 | H12: =IF(H5="","",SUM(H8:H11)) -> 1246305.1 | I12: =IF(I5="","",SUM(I8:I11)) -> 1264870.9 | J12: =IF(J5="","",SUM(J8:J11)) -> 1283713.9 | K12: =IF(K5="","",SUM(K8:K11)) -> 1302838.2 | L12: =IF(L5="","",SUM(L8:L11)) -> 1322248.1 | ... T12: =IF(T5="","",SUM(T8:T11))
B14: - Marketing | E14: =-ABS(Expenses!F6) -> -24800 | F14: =Expenses!G6 -> -25296 | G14: =Expenses!H6 -> -25801.92 | H14: =Expenses!I6 -> -26317.958 | I14: =Expenses!J6 -> -26844.318 | J14: =Expenses!K6 -> -27381.204 | K14: =Expenses!L6 -> -27928.828 | L14: =Expenses!M6 -> -28487.405 | M14: =Expenses!N6 -> -29057.153 | ... T14: =Expenses!U6
B15: - Administrative | E15: =-ABS(Expenses!F7) -> -31000 | F15: =Expenses!G7 -> -31620 | G15: =Expenses!H7 -> -32252.4 | H15: =Expenses!I7 -> -32897.448 | I15: =Expenses!J7 -> -33555.397 | J15: =Expenses!K7 -> -34226.505 | K15: =Expenses!L7 -> -34911.035 | L15: =Expenses!M7 -> -35609.256 | M15: =Expenses!N7 -> -36321.441 | ... T15: =Expenses!U7
B16: - Utilities | E16: =-ABS(Expenses!F8) -> -99200 | F16: =Expenses!G8 -> -101184 | G16: =Expenses!H8 -> -103207.68 | H16: =Expenses!I8 -> -105271.83 | I16: =Expenses!J8 -> -107377.27 | J16: =Expenses!K8 -> -109524.82 | K16: =Expenses!L8 -> -111715.31 | L16: =Expenses!M8 -> -113949.62 | M16: =Expenses!N8 -> -116228.61 | ... T16: =Expenses!U8
B17: - Payroll | E17: =-ABS(Expenses!F9) -> -148800 | F17: =Expenses!G9 -> -151776 | G17: =Expenses!H9 -> -154811.52 | H17: =Expenses!I9 -> -157907.75 | I17: =Expenses!J9 -> -161065.91 | J17: =Expenses!K9 -> -164287.22 | K17: =Expenses!L9 -> -167572.97 | L17: =Expenses!M9 -> -170924.43 | M17: =Expenses!N9 -> -174342.92 | ... T17: =Expenses!U9
B18: -Repair and maintenance | E18: =-ABS(Expenses!F10) -> -86800 | F18: =Expenses!G10 -> -88536 | G18: =Expenses!H10 -> -90306.72 | H18: =Expenses!I10 -> -92112.854 | I18: =Expenses!J10 -> -93955.111 | J18: =Expenses!K10 -> -95834.214 | K18: =Expenses!L10 -> -97750.898 | L18: =Expenses!M10 -> -99705.916 | M18: =Expenses!N10 -> -101700.03 | ... T18: =Expenses!U10
B19: - Mgmt (% of EGR) | E19: =-ABS(Expenses!F11) -> -31631.088 | F19: =Expenses!G11 -> -34320.075 | G19: =Expenses!H11 -> -36840.373 | H19: =Expenses!I11 -> -37389.153 | I19: =Expenses!J11 -> -37946.127 | J19: =Expenses!K11 -> -38511.417 | K19: =Expenses!L11 -> -39085.147 | L19: =Expenses!M11 -> -39667.443 | M19: =Expenses!N11 -> -40258.434 | ... T19: =Expenses!U11
B20: -Insurance | E20: =-ABS(Expenses!F12) -> -27900 | F20: =Expenses!G12 -> -28458 | G20: =Expenses!H12 -> -29027.16 | H20: =Expenses!I12 -> -29607.703 | I20: =Expenses!J12 -> -30199.857 | J20: =Expenses!K12 -> -30803.854 | K20: =Expenses!L12 -> -31419.931 | L20: =Expenses!M12 -> -32048.33 | M20: =Expenses!N12 -> -32689.297 | ... T20: =Expenses!U12
B21: -Taxes | E21: =-ABS(Expenses!F13) -> -167400 | F21: =Expenses!G13 -> -170748 | G21: =Expenses!H13 -> -174162.96 | H21: =Expenses!I13 -> -177646.22 | I21: =Expenses!J13 -> -181199.14 | J21: =Expenses!K13 -> -184823.13 | K21: =Expenses!L13 -> -188519.59 | L21: =Expenses!M13 -> -192289.98 | M21: =Expenses!N13 -> -196135.78 | ... T21: =Expenses!U13
B22: Operating Expenses | D22: =-AVERAGE(E22:T22)/AVERAGE($E$12:$T$12) -> 0.54172858 | E22: =Expenses!F14 -> -617531.09 | F22: =Expenses!G14 -> -631938.07 | G22: =Expenses!H14 -> -646410.73 | H22: =Expenses!I14 -> -659150.92 | I22: =Expenses!J14 -> -672143.13 | J22: =Expenses!K14 -> -685392.36 | K22: =Expenses!L14 -> -698903.71 | L22: =Expenses!M14 -> -712682.38 | ... T22: =Expenses!U14
B24: Net Operating Income | D24: =AVERAGE(E24:T24)/AVERAGE($E$12:$T$12) -> 0.45827142 | E24: =IF(E5="","",E22+E12) -> 436838.51 | F24: =IF(F5="","",F22+F12) -> 512064.41 | G24: =IF(G5="","",G22+G12) -> 581601.71 | H24: =IF(H5="","",H22+H12) -> 587154.19 | I24: =IF(I5="","",I22+I12) -> 592727.77 | J24: =IF(J5="","",J22+J12) -> 598321.53 | K24: =IF(K5="","",K22+K12) -> 603934.51 | L24: =IF(L5="","",L22+L12) -> 609565.73 | ... T24: =IF(T5="","",T22+T12)
B26: - Releasing Costs | E26: =IF(E5="","",-SUMIF('MF Releasing'!$S$3:$GP$3,'Annual Cash Flow'!E5,'MF Releasing'!$S$40:$GP$40)) -> 0 | F26: =IF(F5="","",-SUMIF('MF Releasing'!$S$3:$GP$3,'Annual Cash Flow'!F5,'MF Releasing'!$S$40:$GP$40)) -> -16891.2 | G26: =IF(G5="","",-SUMIF('MF Releasing'!$S$3:$GP$3,'Annual Cash Flow'!G5,'MF Releasing'!$S$40:$GP$40)) -> -17229.024 | H26: =IF(H5="","",-SUMIF('MF Releasing'!$S$3:$GP$3,'Annual Cash Flow'!H5,'MF Releasing'!$S$40:$GP$40)) -> -17573.604 | I26: =IF(I5="","",-SUMIF('MF Releasing'!$S$3:$GP$3,'Annual Cash Flow'!I5,'MF Releasing'!$S$40:$GP$40)) -> -17925.077 | J26: =IF(J5="","",-SUMIF('MF Releasing'!$S$3:$GP$3,'Annual Cash Flow'!J5,'MF Releasing'!$S$40:$GP$40)) -> -18283.578 | K26: =IF(K5="","",-SUMIF('MF Releasing'!$S$3:$GP$3,'Annual Cash Flow'!K5,'MF Releasing'!$S$40:$GP$40)) -> -18649.25 | L26: =IF(L5="","",-SUMIF('MF Releasing'!$S$3:$GP$3,'Annual Cash Flow'!L5,'MF Releasing'!$S$40:$GP$40)) -> -19022.235 | ... T26: =IF(T5="","",-SUMIF('MF Releasing'!$S$3:$GP$3,'Annual Cash Flow'!T5,'MF Releasing'!$S$40:$GP$40))
B27: - Value Add Costs | E27: =Expenses!F20 -> -350000 | F27: =Expenses!G20 -> -200000 | G27: =Expenses!H20 -> 0 | H27: =Expenses!I20 -> 0 | I27: =Expenses!J20 -> 0 | J27: =Expenses!K20 -> 0 | K27: =Expenses!L20 -> 0 | L27: =Expenses!M20 -> 0 | ... S27: =Expenses!T20
B28: - Misc. CapEx | E28: =IF(E5="","",-SUMIF('MF CapEx'!$S$3:$GP$3,'Annual Cash Flow'!E5,'MF CapEx'!$S$40:$GP$40)) -> -85200 | F28: =IF(F5="","",-SUMIF('MF CapEx'!$S$3:$GP$3,'Annual Cash Flow'!F5,'MF CapEx'!$S$40:$GP$40)) -> -86904 | G28: =IF(G5="","",-SUMIF('MF CapEx'!$S$3:$GP$3,'Annual Cash Flow'!G5,'MF CapEx'!$S$40:$GP$40)) -> -88642.08 | H28: =IF(H5="","",-SUMIF('MF CapEx'!$S$3:$GP$3,'Annual Cash Flow'!H5,'MF CapEx'!$S$40:$GP$40)) -> -90414.922 | I28: =IF(I5="","",-SUMIF('MF CapEx'!$S$3:$GP$3,'Annual Cash Flow'!I5,'MF CapEx'!$S$40:$GP$40)) -> -92223.22 | J28: =IF(J5="","",-SUMIF('MF CapEx'!$S$3:$GP$3,'Annual Cash Flow'!J5,'MF CapEx'!$S$40:$GP$40)) -> -94067.684 | K28: =IF(K5="","",-SUMIF('MF CapEx'!$S$3:$GP$3,'Annual Cash Flow'!K5,'MF CapEx'!$S$40:$GP$40)) -> -95949.038 | L28: =IF(L5="","",-SUMIF('MF CapEx'!$S$3:$GP$3,'Annual Cash Flow'!L5,'MF CapEx'!$S$40:$GP$40)) -> -97868.019 | ... T28: =IF(T5="","",-SUMIF('MF CapEx'!$S$3:$GP$3,'Annual Cash Flow'!T5,'MF CapEx'!$S$40:$GP$40))
B29: Capital Expenditures | D29: =-AVERAGE(E29:T29)/AVERAGE($E$12:$T$12) -> 0.1271653 | E29: =IF(E5="","",SUM(E26:E28)) -> -435200 | F29: =IF(F5="","",SUM(F26:F28)) -> -303795.2 | G29: =IF(G5="","",SUM(G26:G28)) -> -105871.1 | H29: =IF(H5="","",SUM(H26:H28)) -> -107988.53 | I29: =IF(I5="","",SUM(I26:I28)) -> -110148.3 | J29: =IF(J5="","",SUM(J26:J28)) -> -112351.26 | K29: =IF(K5="","",SUM(K26:K28)) -> -114598.29 | L29: =IF(L5="","",SUM(L26:L28)) -> -116890.25 | ... T29: =IF(T5="","",SUM(T26:T28))
B31: Cash Flow From Operations | D31: =AVERAGE(E31:T31)/AVERAGE($E$24:$T$24) -> 0.72251097 | E31: =IF(E5="","",E29+E24) -> 1638.512 | F31: =IF(F5="","",F29+F24) -> 208269.21 | G31: =IF(G5="","",G29+G24) -> 475730.6 | H31: =IF(H5="","",H29+H24) -> 479165.67 | I31: =IF(I5="","",I29+I24) -> 482579.48 | J31: =IF(J5="","",J29+J24) -> 485970.27 | K31: =IF(K5="","",K29+K24) -> 489336.23 | L31: =IF(L5="","",L29+L24) -> 492675.48 | ... T31: =IF(T5="","",T29+T24)

Sheet Property Returns
B2: Property Level Returns
D3: 1 | E3: =IF(OR(D3="",D3=Analysis_Period),"",D3+1) -> 2 | F3: =IF(OR(E3="",E3=Cap_Year),"",E3+1) -> 3 | G3: =IF(OR(F3="",F3=Cap_Year),"",F3+1) -> 4 | H3: =IF(OR(G3="",G3=Cap_Year),"",G3+1) -> 5 | I3: =IF(OR(H3="",H3=Cap_Year),"",H3+1) -> 6 | J3: =IF(OR(I3="",I3=Cap_Year),"",I3+1) -> 7 | K3: =IF(OR(J3="",J3=Cap_Year),"",J3+1) -> 8 | L3: =IF(OR(K3="",K3=Cap_Year),"",K3+1) -> 9 | M3: =IF(OR(L3="",L3=Cap_Year),"",L3+1) -> 10 | ... R3: =IF(OR(Q3="",Q3=Cap_Year),"",Q3+1) | S3: =IF(OR(R3="",R3=Analysis_Period),"",R3+1) | T3: =IF(OR(S3="",S3=Analysis_Period),"",S3+1)
B4: . | C4: Year Ending | D4: =EOMONTH(Analysis_Start,11) -> 42735 | E4: =IF(E3="","",EOMONTH(Analysis_Start,(11*E3)+D3)) -> 43100 | F4: =IF(F3="","",EOMONTH(Analysis_Start,(11*F3)+E3)) -> 43465 | G4: =IF(G3="","",EOMONTH(Analysis_Start,(11*G3)+F3)) -> 43830 | H4: =IF(H3="","",EOMONTH(Analysis_Start,(11*H3)+G3)) -> 44196 | I4: =IF(I3="","",EOMONTH(Analysis_Start,(11*I3)+H3)) -> 44561 | J4: =IF(J3="","",EOMONTH(Analysis_Start,(11*J3)+I3)) -> 44926 | K4: =IF(K3="","",EOMONTH(Analysis_Start,(11*K3)+J3)) -> 45291 | L4: =IF(L3="","",EOMONTH(Analysis_Start,(11*L3)+K3)) -> 45657 | ... R4: =IF(R3="","",EOMONTH(Analysis_Start,(11*R3)+Q3))
B5: ='Annual Cash Flow'!B12 -> Effective Gross Revenue | D5: ='Annual Cash Flow'!E12 -> 1054369.6 | E5: ='Annual Cash Flow'!F12 -> 1144002.5 | F5: ='Annual Cash Flow'!G12 -> 1228012.4 | G5: ='Annual Cash Flow'!H12 -> 1246305.1 | H5: ='Annual Cash Flow'!I12 -> 1264870.9 | I5: ='Annual Cash Flow'!J12 -> 1283713.9 | J5: ='Annual Cash Flow'!K12 -> 1302838.2 | K5: ='Annual Cash Flow'!L12 -> 1322248.1 | ... R5: ='Annual Cash Flow'!S12
B6: =Expenses!C14 -> Operating Expenses | D6: ='Annual Cash Flow'!E22 -> -617531.09 | E6: =Expenses!G14 -> -631938.07 | F6: =Expenses!H14 -> -646410.73 | G6: =Expenses!I14 -> -659150.92 | H6: =Expenses!J14 -> -672143.13 | I6: =Expenses!K14 -> -685392.36 | J6: =Expenses!L14 -> -698903.71 | K6: =Expenses!M14 -> -712682.38 | L6: =Expenses!N14 -> -726733.67 | ... R6: =Expenses!T14
B7: ='Annual Cash Flow'!B24 -> Net Operating Income | D7: ='Annual Cash Flow'!E24 -> 436838.51 | E7: ='Annual Cash Flow'!F24 -> 512064.41 | F7: ='Annual Cash Flow'!G24 -> 581601.71 | G7: ='Annual Cash Flow'!H24 -> 587154.19 | H7: ='Annual Cash Flow'!I24 -> 592727.77 | I7: ='Annual Cash Flow'!J24 -> 598321.53 | J7: ='Annual Cash Flow'!K24 -> 603934.51 | K7: ='Annual Cash Flow'!L24 -> 609565.73 | ... R7: ='Annual Cash Flow'!S24
B8: ='Annual Cash Flow'!B29 -> Capital Expenditures | D8: ='Annual Cash Flow'!E29 -> -435200 | E8: ='Annual Cash Flow'!F29 -> -303795.2 | F8: ='Annual Cash Flow'!G29 -> -105871.1 | G8: ='Annual Cash Flow'!H29 -> -107988.53 | H8: ='Annual Cash Flow'!I29 -> -110148.3 | I8: ='Annual Cash Flow'!J29 -> -112351.26 | J8: ='Annual Cash Flow'!K29 -> -114598.29 | K8: ='Annual Cash Flow'!L29 -> -116890.25 | ... R8: ='Annual Cash Flow'!S29
B9: ='Annual Cash Flow'!B31 -> Cash Flow From Operations | D9: ='Annual Cash Flow'!E31 -> 1638.512 | E9: ='Annual Cash Flow'!F31 -> 208269.21 | F9: ='Annual Cash Flow'!G31 -> 475730.6 | G9: ='Annual Cash Flow'!H31 -> 479165.67 | H9: ='Annual Cash Flow'!I31 -> 482579.48 | I9: ='Annual Cash Flow'!J31 -> 485970.27 | J9: ='Annual Cash Flow'!K31 -> 489336.23 | K9: ='Annual Cash Flow'!L31 -> 492675.48 | ... R9: ='Annual Cash Flow'!S31
B11: Cap Rate at Sale | D11: =Exit_Cap_Yr_1 -> 0.065 | E11: =IF(E5="","",IF(E3>Analysis_Period,"",D11+'Property Summary'!$D$10/10000)) -> 0.065 | F11: =IF(F5="","",IF(F3>Analysis_Period,"",E11+'Property Summary'!$D$10/10000)) -> 0.065 | G11: =IF(G5="","",IF(G3>Analysis_Period,"",F11+'Property Summary'!$D$10/10000)) -> 0.065 | H11: =IF(H5="","",IF(H3>Analysis_Period,"",G11+'Property Summary'!$D$10/10000)) -> 0.065 | I11: =IF(I5="","",IF(I3>Analysis_Period,"",H11+'Property Summary'!$D$10/10000)) -> 0.065 | J11: =IF(J5="","",IF(J3>Analysis_Period,"",I11+'Property Summary'!$D$10/10000)) -> 0.065 | K11: =IF(K5="","",IF(K3>Analysis_Period,"",J11+'Property Summary'!$D$10/10000)) -> 0.065 | L11: =IF(L5="","",IF(L3>Analysis_Period,"",K11+'Property Summary'!$D$10/10000)) -> 0.065 | ... R11: =IF(R5="","",IF(R3>Analysis_Period,"",Q11+'Property Summary'!$D$10/10000))
B12: Net Sales Price | D12: =IFERROR(HLOOKUP(Cap_Year-Analysis_Period+D3,$D$3:$R$9,5,FALSE)/D11,"") -> 7877914.1 | E12: =IFERROR(HLOOKUP(Cap_Year-Analysis_Period+E3,$D$3:$R$9,5,FALSE)/E11,"") -> 8947718.5 | F12: =IFERROR(HLOOKUP(Cap_Year-Analysis_Period+F3,$D$3:$R$9,5,FALSE)/F11,"") -> 9033141.4 | G12: =IFERROR(HLOOKUP(Cap_Year-Analysis_Period+G3,$D$3:$R$9,5,FALSE)/G11,"") -> 9118888.8 | H12: =IFERROR(HLOOKUP(Cap_Year-Analysis_Period+H3,$D$3:$R$9,5,FALSE)/H11,"") -> 9204946.6 | I12: =IFERROR(HLOOKUP(Cap_Year-Analysis_Period+I3,$D$3:$R$9,5,FALSE)/I11,"") -> 9291300.2 | J12: =IFERROR(HLOOKUP(Cap_Year-Analysis_Period+J3,$D$3:$R$9,5,FALSE)/J11,"") -> 9377934.3 | K12: =IFERROR(HLOOKUP(Cap_Year-Analysis_Period+K3,$D$3:$R$9,5,FALSE)/K11,"") -> 9464833 | ... Q12: =IFERROR(HLOOKUP(Cap_Year-Analysis_Period+Q3,$D$3:$R$9,5,FALSE)/Q11,"") | R12: =IFERROR(HLOOKUP(Cap_Year-Analysis_Period+R3,$D$3:$R$9,5,FALSE)/R11,0) -> 0
B13: Net Sales Price PSF | D13: =IFERROR(D12/Units,"") -> 63531.565 | E13: =IFERROR(E12/Units,"") -> 72159.021 | F13: =IFERROR(F12/Units,"") -> 72847.915 | G13: =IFERROR(G12/Units,"") -> 73539.426 | H13: =IFERROR(H12/Units,"") -> 74233.441 | I13: =IFERROR(I12/Units,"") -> 74929.84 | J13: =IFERROR(J12/Units,"") -> 75628.502 | K13: =IFERROR(K12/Units,"") -> 76329.298 | ... R13: =IFERROR(R12/Units,"") -> 0
B15: Cash Flow from Operations | D15: =D9 -> 1638.512 | E15: =IF(E3>Analysis_Period,"",E9) -> 208269.21 | F15: =IF(F3>Analysis_Period,"",F9) -> 475730.6 | G15: =IF(G3>Analysis_Period,"",G9) -> 479165.67 | H15: =IF(H3>Analysis_Period,"",H9) -> 482579.48 | I15: =IF(I3>Analysis_Period,"",I9) -> 485970.27 | J15: =IF(J3>Analysis_Period,"",J9) -> 489336.23 | K15: =IF(K3>Analysis_Period,"",K9) -> 492675.48 | L15: =IF(L3>Analysis_Period,"",L9) -> 495986.09 | ... R15: =IF(R3>Analysis_Period,"",R9)
B16: Free and Clear Return | D16: =IF(D9="","",D9/(-D48)) -> 0.00022233316 | E16: =IF(E9="","",IF(E3>Analysis_Period,"",E9/(-E48))) -> 0.02826049 | F16: =IF(F9="","",IF(F3>Analysis_Period,"",F9/(-F48))) -> 0.064552891 | G16: =IF(G9="","",IF(G3>Analysis_Period,"",G9/(-G48))) -> 0.065019002 | H16: =IF(H9="","",IF(H3>Analysis_Period,"",H9/(-H48))) -> 0.06548223 | I16: =IF(I9="","",IF(I3>Analysis_Period,"",I9/(-I48))) -> 0.065942333 | J16: =IF(J9="","",IF(J3>Analysis_Period,"",J9/(-J48))) -> 0.066399067 | K16: =IF(K9="","",IF(K3>Analysis_Period,"",K9/(-K48))) -> 0.066852177 | L16: =IF(L9="","",IF(L3>Analysis_Period,"",L9/(-L48))) -> 0.067301401 | ... R16: =IF(R9="","",IF(R3>Analysis_Period,"",R9/(-R48)))
B17: Avg. Free and Clear Return | D17: =IF(D16="","",AVERAGE($D$16:D16)) -> 0.00022233316 | E17: =IF(E16="","",AVERAGE($D$16:E16)) -> 0.014241412 | F17: =IF(F16="","",AVERAGE($D$16:F16)) -> 0.031011905 | G17: =IF(G16="","",AVERAGE($D$16:G16)) -> 0.039513679 | H17: =IF(H16="","",AVERAGE($D$16:H16)) -> 0.044707389 | I17: =IF(I16="","",AVERAGE($D$16:I16)) -> 0.048246547 | J17: =IF(J16="","",AVERAGE($D$16:J16)) -> 0.050839764 | K17: =IF(K16="","",AVERAGE($D$16:K16)) -> 0.052841316 | ... R17: =IF(R16="","",AVERAGE($D$16:R16))
B18: Unlevered CF w/Residual | D18: =IF(D3=Analysis_Period,D12+D15,D15) -> 1638.512 | E18: =IF(E3=Analysis_Period,E12+E15,E15) -> 208269.21 | F18: =IF(F3=Analysis_Period,F12+F15,F15) -> 475730.6 | G18: =IF(G3=Analysis_Period,G12+G15,G15) -> 479165.67 | H18: =IF(H3=Analysis_Period,H12+H15,H15) -> 482579.48 | I18: =IF(I3=Analysis_Period,I12+I15,I15) -> 485970.27 | J18: =IF(J3=Analysis_Period,J12+J15,J15) -> 489336.23 | K18: =IF(K3=Analysis_Period,K12+K15,K15) -> 492675.48 | ... R18: =IF(R3=Analysis_Period,R12+R15,R15)
B20: Unlevered Internal Rate of Return | D20: =D47 -> 0.069193149 | E20: =IF(E3>Analysis_Period,"",E47) -> 0.11473907 | F20: =IF(F3>Analysis_Period,"",F47) -> 0.097393158 | G20: =IF(G3>Analysis_Period,"",G47) -> 0.089014215 | H20: =IF(H3>Analysis_Period,"",H47) -> 0.08406345 | I20: =IF(I3>Analysis_Period,"",I47) -> 0.080784406 | J20: =IF(J3>Analysis_Period,"",J47) -> 0.078445543 | K20: =IF(K3>Analysis_Period,"",K47) -> 0.076687915 | L20: =IF(L3>Analysis_Period,"",L47) -> 0.075314764 | ... R20: =IF(R3>Analysis_Period,"",R47)
B21: Unlevered Equity Multiple | D21: =IF(D46="","",SUMIF(D48:D63,">0")/-SUMIF(D48:D63,"<0")) -> 1.0691931 | E21: =IF(E46="","",SUMIF(E48:E63,">0")/-SUMIF(E48:E63,"<0")) -> 1.2426177 | F21: =IF(F46="","",SUMIF(F48:F63,">0")/-SUMIF(F48:F63,"<0")) -> 1.3187618 | G21: =IF(G46="","",SUMIF(G48:G63,">0")/-SUMIF(G48:G63,"<0")) -> 1.395416 | H21: =IF(H46="","",SUMIF(H48:H63,">0")/-SUMIF(H48:H63,"<0")) -> 1.4725756 | I21: =IF(I46="","",SUMIF(I48:I63,">0")/-SUMIF(I48:I63,"<0")) -> 1.5502355 | J21: =IF(J46="","",SUMIF(J48:J63,">0")/-SUMIF(J48:J63,"<0")) -> 1.6283901 | K21: =IF(K46="","",SUMIF(K48:K63,">0")/-SUMIF(K48:K63,"<0")) -> 1.7070337 | ... R21: =IF(R46="","",SUMIF(R48:R63,">0")/-SUMIF(R48:R63,"<0"))
B23: Portion of IRR from Income | D23: =IFERROR(D17/D20,"") -> 0.003213225 | E23: =IFERROR(E17/E20,"") -> 0.12411999 | F23: =IFERROR(F17/F20,"") -> 0.31841975 | G23: =IFERROR(G17/G20,"") -> 0.44390302 | H23: =IFERROR(H17/H20,"") -> 0.53182911 | I23: =IFERROR(I17/I20,"") -> 0.59722599 | J23: =IFERROR(J17/J20,"") -> 0.6480899 | K23: =IFERROR(K17/K20,"") -> 0.68904358 | ... R23: =IFERROR(R17/R20,"")
B24: Portion of IRR from Sale | D24: =IFERROR(1-D23,"") -> 0.99678677 | E24: =IFERROR(1-E23,"") -> 0.87588001 | F24: =IFERROR(1-F23,"") -> 0.68158025 | G24: =IFERROR(1-G23,"") -> 0.55609698 | H24: =IFERROR(1-H23,"") -> 0.46817089 | I24: =IFERROR(1-I23,"") -> 0.40277401 | J24: =IFERROR(1-J23,"") -> 0.3519101 | K24: =IFERROR(1-K23,"") -> 0.31095642 | ... R24: =IFERROR(1-R23,"")
O25: =#REF! -> #REF! | P25: =#REF! -> #REF! | Q25: =#REF! -> #REF! | R25: =#REF! -> #REF!
B26: Debt Service | D26: =Debt!D6 -> 278192.01 | E26: =Debt!E6 -> 278192.01 | F26: =Debt!F6 -> 278192.01 | G26: =Debt!G6 -> 278192.01 | H26: =Debt!H6 -> 278192.01 | I26: =Debt!I6 -> 278192.01 | J26: =Debt!J6 -> 278192.01 | K26: =Debt!K6 -> 278192.01 | ... R26: =Debt!R6
B27: Debt Coverage Ratio (NOI) | D27: =IFERROR(D7/D26,"") -> 1.570277 | E27: =IFERROR(E7/E26,"") -> 1.840687 | F27: =IFERROR(F7/F26,"") -> 2.0906485 | G27: =IFERROR(G7/G26,"") -> 2.1106077 | H27: =IFERROR(H7/H26,"") -> 2.1306427 | I27: =IFERROR(I7/I26,"") -> 2.1507502 | J27: =IFERROR(J7/J26,"") -> 2.1709269 | K27: =IFERROR(K7/K26,"") -> 2.1911691 | ... R27: =IFERROR(R7/R26,"")
B28: Debt Yield (NOI) | D28: =IFERROR(D7/D29,"") -> 0.094287387 | E28: =IFERROR(E7/E29,"") -> 0.11253757 | F28: =IFERROR(F7/F29,"") -> 0.13029639 | G28: =IFERROR(G7/G29,"") -> 0.13425415 | H28: =IFERROR(H7/H29,"") -> 0.13851004 | I28: =IFERROR(I7/I29,"") -> 0.14310171 | J28: =IFERROR(J7/J29,"") -> 0.14807338 | K28: =IFERROR(K7/K29,"") -> 0.15347732 | ... R28: =IFERROR(R7/R29,"")
B29: Loan Balance | D29: =Debt!D7 -> 4633053.5 | E29: =Debt!E7 -> 4550164.1 | F29: =Debt!F7 -> 4463682.3 | G29: =Debt!G7 -> 4373452.7 | H29: =Debt!H7 -> 4279312.7 | I29: =Debt!I7 -> 4181092.9 | J29: =Debt!J7 -> 4078616.5 | K29: =Debt!K7 -> 3971699 | ... R29: =Debt!R7
B31: Net Cash on Sale | D31: =IFERROR(D12-D29,"") -> 3244860.5 | E31: =IFERROR(E12-E29,"") -> 4397554.5 | F31: =IFERROR(F12-F29,"") -> 4569459.1 | G31: =IFERROR(G12-G29,"") -> 4745436.1 | H31: =IFERROR(H12-H29,"") -> 4925633.9 | I31: =IFERROR(I12-I29,"") -> 5110207.3 | J31: =IFERROR(J12-J29,"") -> 5299317.8 | K31: =IFERROR(K12-K29,"") -> 5493134 | ... R31: =IFERROR(R12-R29,"")
B32: Net Gain | D32: =IFERROR(D31-(-D68),"") -> 587735.51 | E32: =IFERROR(E31-(-E68),"") -> 1740429.5 | F32: =IFERROR(F31-(-F68),"") -> 1912334.1 | G32: =IFERROR(G31-(-G68),"") -> 2088311.1 | H32: =IFERROR(H31-(-H68),"") -> 2268508.9 | I32: =IFERROR(I31-(-I68),"") -> 2453082.3 | J32: =IFERROR(J31-(-J68),"") -> 2642192.8 | K32: =IFERROR(K31-(-K68),"") -> 2836009 | ... R32: =IFERROR(R31-(-R68),"")
O33: =O35 | P33: =P35 | Q33: =Q35 | R33: =R35
B34: Cash Flow after Financing | D34: =IFERROR(D9-D26,"") -> -276553.5 | E34: =IFERROR(E9-E26,"") -> -69922.795 | F34: =IFERROR(F9-F26,"") -> 197538.59 | G34: =IFERROR(G9-G26,"") -> 200973.66 | H34: =IFERROR(H9-H26,"") -> 204387.47 | I34: =IFERROR(I9-I26,"") -> 207778.26 | J34: =IFERROR(J9-J26,"") -> 211144.22 | K34: =IFERROR(K9-K26,"") -> 214483.47 | ... R34: =IFERROR(R9-R26,"")
B35: Cash-on-Cash Return | D35: =IF(D34="","",D34/(-D68)) -> -0.10407997 | E35: =IF(E34="","",E34/(-E68)) -> -0.026315207 | F35: =IF(F34="","",F34/(-F68)) -> 0.074342981 | G35: =IF(G34="","",G34/(-G68)) -> 0.075635756 | H35: =IF(H34="","",H34/(-H68)) -> 0.076920532 | I35: =IF(I34="","",I34/(-I68)) -> 0.078196645 | J35: =IF(J34="","",J34/(-J68)) -> 0.079463412 | K35: =IF(K34="","",K34/(-K68)) -> 0.080720127 | ... R35: =IF(R34="","",R34/(-R68))
B36: Avg. Cash-on-Cash Return | D36: =IF(D35="","",AVERAGE($D$35:D35)) -> -0.10407997 | E36: =IF(E35="","",AVERAGE($D$35:E35)) -> -0.06519759 | F36: =IF(F35="","",AVERAGE($D$35:F35)) -> -0.018684066 | G36: =IF(G35="","",AVERAGE($D$35:G35)) -> 0.0048958893 | H36: =IF(H35="","",AVERAGE($D$35:H35)) -> 0.019300818 | I36: =IF(I35="","",AVERAGE($D$35:I35)) -> 0.029116789 | J36: =IF(J35="","",AVERAGE($D$35:J35)) -> 0.036309164 | K36: =IF(K35="","",AVERAGE($D$35:K35)) -> 0.041860534 | ... R36: =IF(R35="","",AVERAGE($D$35:R35))
O37: =O39 | P37: =P39 | Q37: =Q39 | R37: =R39
B38: Levered Internal Rate of Return | D38: =D67 -> 0.1171123 | E38: =E67 -> 0.22522181 | F38: =F67 -> 0.17436362 | G38: =G67 -> 0.15076411 | H38: =H67 -> 0.13699266 | I38: =I67 -> 0.1278684 | J38: =J67 -> 0.12131219 | K38: =K67 -> 0.11632809 | ... R38: =R67
B39: Levered Equity Multiple | D39: =IF(D46="","",SUMIF(D68:D83,">0")/-SUMIF(D68:D83,"<0")) -> 1.1171123 | E39: =IF(E46="","",SUMIF(E68:E83,">0")/-SUMIF(E68:E83,"<0")) -> 1.4751554 | F39: =IF(F46="","",SUMIF(F68:F83,">0")/-SUMIF(F68:F83,"<0")) -> 1.587094 | G39: =IF(G46="","",SUMIF(G68:G83,">0")/-SUMIF(G68:G83,"<0")) -> 1.7125936 | H39: =IF(H46="","",SUMIF(H68:H83,">0")/-SUMIF(H68:H83,"<0")) -> 1.840635 | I39: =IF(I46="","",SUMIF(I68:I83,">0")/-SUMIF(I68:I83,"<0")) -> 1.9712621 | J39: =IF(J46="","",SUMIF(J68:J83,">0")/-SUMIF(J68:J83,"<0")) -> 2.1045203 | K39: =IF(K46="","",SUMIF(K68:K83,">0")/-SUMIF(K68:K83,"<0")) -> 2.2404571 | ... R39: =IF(R46="","",SUMIF(R68:R83,">0")/-SUMIF(R68:R83,"<0"))
B41: Levered Before Tax Cash Flow | D41: =IF(D3=Analysis_Period,D31+D34,D34) -> -276553.5 | E41: =IF(E3=Analysis_Period,E31+E34,E34) -> -69922.795 | F41: =IF(F3=Analysis_Period,F31+F34,F34) -> 197538.59 | G41: =IF(G3=Analysis_Period,G31+G34,G34) -> 200973.66 | H41: =IF(H3=Analysis_Period,H31+H34,H34) -> 204387.47 | I41: =IF(I3=Analysis_Period,I31+I34,I34) -> 207778.26 | J41: =IF(J3=Analysis_Period,J31+J34,J34) -> 211144.22 | K41: =IF(K3=Analysis_Period,K31+K34,K34) -> 214483.47 | ... R41: =IF(R3=Analysis_Period,R31+R34,R34)
B44: Internal Rate of Return Calculation (Hide/Unhide)
B45: Unlevered
B46: Year | D46: =IF(D12="","",D3) -> 1 | E46: =IF(E12="","",E3) -> 2 | F46: =IF(F12="","",F3) -> 3 | G46: =IF(G12="","",G3) -> 4 | H46: =IF(H12="","",H3) -> 5 | I46: =IF(I12="","",I3) -> 6 | J46: =IF(J12="","",J3) -> 7 | K46: =IF(K12="","",K3) -> 8 | ... R46: =IF(R12="","",R3)
B47: IRR | D47: =IF(D46="","",IRR(D48:D63)) -> 0.069193149 | E47: =IF(E46="","",IRR(E48:E63)) -> 0.11473907 | F47: =IF(F46="","",IRR(F48:F63)) -> 0.097393158 | G47: =IF(G46="","",IRR(G48:G63)) -> 0.089014215 | H47: =IF(H46="","",IRR(H48:H63)) -> 0.08406345 | I47: =IF(I46="","",IRR(I48:I63)) -> 0.080784406 | J47: =IF(J46="","",IRR(J48:J63)) -> 0.078445543 | K47: =IF(K46="","",IRR(K48:K63)) -> 0.076687915 | ... R47: =IF(R46="","",IRR(R48:R63))
B48: 0 | D48: =IF(D46="","",-(Basis)) -> -7369625 | E48: =IF(E46="","",-(Basis)) -> -7369625 | F48: =IF(F46="","",-(Basis)) -> -7369625 | G48: =IF(G46="","",-(Basis)) -> -7369625 | H48: =IF(H46="","",-(Basis)) -> -7369625 | I48: =IF(I46="","",-(Basis)) -> -7369625 | J48: =IF(J46="","",-(Basis)) -> -7369625 | K48: =IF(K46="","",-(Basis)) -> -7369625 | ... R48: =IF(R46="","",-(Basis))
B49: =B48+1 -> 1 | D49: =IF($B49>D$46,"",IF(D$46="","",IF(D$46=$B49,OFFSET($D$15,0,$B48)+OFFSET($D$12,0,$B48),OFFSET($D$15,0,$B48)))) -> 7879552.6 | E49: =IF($B49>E$46,"",IF(E$46="","",IF(E$46=$B49,OFFSET($D$15,0,$B48)+OFFSET($D$12,0,$B48),OFFSET($D$15,0,$B48)))) -> 1638.512 | F49: =IF($B49>F$46,"",IF(F$46="","",IF(F$46=$B49,OFFSET($D$15,0,$B48)+OFFSET($D$12,0,$B48),OFFSET($D$15,0,$B48)))) -> 1638.512 | G49: =IF($B49>G$46,"",IF(G$46="","",IF(G$46=$B49,OFFSET($D$15,0,$B48)+OFFSET($D$12,0,$B48),OFFSET($D$15,0,$B48)))) -> 1638.512 | H49: =IF($B49>H$46,"",IF(H$46="","",IF(H$46=$B49,OFFSET($D$15,0,$B48)+OFFSET($D$12,0,$B48),OFFSET($D$15,0,$B48)))) -> 1638.512 | I49: =IF($B49>I$46,"",IF(I$46="","",IF(I$46=$B49,OFFSET($D$15,0,$B48)+OFFSET($D$12,0,$B48),OFFSET($D$15,0,$B48)))) -> 1638.512 | J49: =IF($B49>J$46,"",IF(J$46="","",IF(J$46=$B49,OFFSET($D$15,0,$B48)+OFFSET($D$12,0,$B48),OFFSET($D$15,0,$B48)))) -> 1638.512 | K49: =IF($B49>K$46,"",IF(K$46="","",IF(K$46=$B49,OFFSET($D$15,0,$B48)+OFFSET($D$12,0,$B48),OFFSET($D$15,0,$B48)))) -> 1638.512 | ... R49: =IF($B49>R$46,"",IF(R$46="","",IF(R$46=$B49,OFFSET($D$15,0,$B48)+OFFSET($D$12,0,$B48),OFFSET($D$15,0,$B48))))
...

Sheet Investor Returns
B2: Property Level Returns
B4: Promote Structure Method | D4: IRR | E4: =IF(D4="Equity Multiple",0,1) -> 1
B5: Return of Capital | D5: Pari Passu
B7: Equity Contributions | C7: % | D7: Amount
B8: Sponsor | C8: 0.1 | D8: =Equity_Share_Sponsor*Total_Equity -> 300360.13 | E8: =Equity_Share_Sponsor=1 -> FALSE | K8: Error Check: | L8: =IF(ROUND(L10,0)=ROUND(L9,0),"OK","Error") -> OK
B9: LP Investors | C9: =1-C8 -> 0.9 | D9: =Total_Equity*Equity_Share_LP -> 2703241.2 | K9: Profit Dist.: | L9: =(D23+D31)/1000000 -> 4.5671675
B10: Total Equity | D10: =-SUMIF(F40:U40,"<0") -> 3003601.3 | K10: Net BTCF: | L10: =SUM(F37:U37)/1000000 -> 4.5671675
F12: Promote Structure Incentive Breakdown | H12: Distribution as %
B13: =IF(D4="Equity Multiple","Promote Structure (Equity Multiple Hurdles)","Promote Structure (IRR Hurdles)") -> Promote Structure (IRR Hurdles) | H13: Sponsor % | I13: LP % | J13: Notes
B14: Hurdle 1 (Preferred Return) | C14: Equity Multiple | D14: Pref | E14: =IF($D$4="Equity Multiple",C15,D15) -> 0.08 | F14: Sponsor Promote | H14: =Equity_Share_Sponsor -> 0.1 | I14: =1-H14 -> 0.9 | J14: =IF(I14=Equity_Share_LP,"Pref prorata to LP/Sponsor, then Pro rata return of capital","Return of capital and Pref NOT pro rata") -> Pref prorata to LP/Sponsor, then Pro rata return of capital
B15: Hurdle 2 | C15: 2 | D15: 0.08 | E15: =IF($D$4="Equity Multiple",C16,D16) -> 0.12 | F15: 0.2 | H15: =1-(Equity_Share_LP*(1-F15)) -> 0.28 | I15: =1-H15 -> 0.72 | J15: =IF(Equity_Share_Sponsor<>H14,TEXT(I14,"0.0%")&"/"&TEXT(H14,"0.0%")&" to "&(IF(D4="IRR",TEXT(E14,"0.0%"),TEXT(E14,"0.0X")))&", then "&TEXT(I15,"0.0%")&"/"&TEXT(H15,"0.0%")&" to "&(IF(D4="IRR",TEXT(E15,"0.0%"),TEXT(E15,"0.0X"))),"Prorata to LP/Sponsor to "&(IF(D4="IRR",TEXT(E14,"0.0%"),TEXT(E14,"0.0X")))&", then "&TEXT(I15,"0.0%")&"/"&TEXT(H15,"0.0%")&" to "&(IF(D4="IRR",TEXT(E15,"0.0%"),TEXT(E15,"0.0X")))) -> Prorata to LP/Sponsor to 8.0%, then 72.0%/28.0% to 12.0%
B16: Hurdle 3 | C16: 2.5 | D16: 0.12 | E16: =IF($D$4="Equity Multiple",C17,D17) -> 0.15 | F16: 0.3 | H16: =1-(Equity_Share_LP*(1-F16)) -> 0.37 | I16: =1-H16 -> 0.63 | J16: =TEXT(I15,"0.0%")&"/"&TEXT(H15,"0.0%")&" to "&(IF(D4="IRR",TEXT(E15,"0.0%"),TEXT(E15,"0.0X")))&", then "&TEXT(I16,"0.0%")&"/"&TEXT(H16,"0.0%")&" to "&(IF(D4="IRR",TEXT(E16,"0.0%"),TEXT(E16,"0.0X"))) -> 72.0%/28.0% to 12.0%, then 63.0%/37.0% to 15.0%
B17: Hurdle 4 | C17: 3 | D17: 0.15 | F17: 0.4 | H17: =1-(Equity_Share_LP*(1-F17)) -> 0.46 | I17: =1-H17 -> 0.54 | J17: =TEXT(I16,"0.0%")&"/"&TEXT(H16,"0.0%")&" to "&(IF(D4="IRR",TEXT(E16,"0.0%"),TEXT(E16,"0.0X")))&", then "&TEXT(I17,"0.0%")&"/"&TEXT(H17,"0.0%")&" thereafter" -> 63.0%/37.0% to 15.0%, then 54.0%/46.0% thereafter
B19: Summary of Investor Level Returns | F19: 0 | G19: =IF(OR(F19="",F19=Analysis_Period),"",F19+1) -> 1 | H19: =IF(OR(G19="",G19=Analysis_Period),"",G19+1) -> 2 | I19: =IF(OR(H19="",H19=Analysis_Period),"",H19+1) -> 3 | J19: =IF(OR(I19="",I19=Analysis_Period),"",I19+1) -> 4 | K19: =IF(OR(J19="",J19=Analysis_Period),"",J19+1) -> 5 | L19: =IF(OR(K19="",K19=Analysis_Period),"",K19+1) -> 6 | M19: =IF(OR(L19="",L19=Analysis_Period),"",L19+1) -> 7 | N19: =IF(OR(M19="",M19=Analysis_Period),"",M19+1) -> 8 | ... U19: =IF(OR(T19="",T19=Analysis_Period),"",T19+1)
B20: Limited Partner (LP) Returns
B21: Total LP Distributions | D21: =SUM(F21:U21) -> 6509543.7 | F21: =IF(F19="","",IF(GP_Only?,0,F53+F71+F86+F93)) -> 0 | G21: =IF(G19="","",IF(GP_Only?,0,G53+G71+G86+G93)) -> 0 | H21: =IF(H19="","",IF(GP_Only?,0,H53+H71+H86+H93)) -> 0 | I21: =IF(I19="","",IF(GP_Only?,0,I53+I71+I86+I93)) -> 177784.73 | J21: =IF(J19="","",IF(GP_Only?,0,J53+J71+J86+J93)) -> 180876.29 | K21: =IF(K19="","",IF(GP_Only?,0,K53+K71+K86+K93)) -> 183948.72 | L21: =IF(L19="","",IF(GP_Only?,0,L53+L71+L86+L93)) -> 187000.43 | M21: =IF(M19="","",IF(GP_Only?,0,M53+M71+M86+M93)) -> 190029.8 | ... U21: =IF(U19="","",IF(GP_Only?,0,U53+U71+U86+U93))
B22: Total LP Contributions | D22: =SUM(F22:U22) -> 2703241.2 | F22: =F49 -> 2391412.5 | G22: =G49 -> 248898.15 | H22: =H49 -> 62930.516 | I22: =I49 -> 0 | J22: =J49 -> 0 | K22: =K49 -> 0 | L22: =L49 -> 0 | M22: =M49 -> 0 | ... U22: =U49
B23: Total LP Profit | D23: =D21-D22 -> 3806302.5
B24: LP IRR | D24: =IF(GP_Only?,"NA",IRR(F24:U24)) -> 0.10388158 | F24: =IF(F19="","",(-F22)+F21) -> -2391412.5 | G24: =IF(G19="","",(-G22)+G21) -> -248898.15 | H24: =IF(H19="","",(-H22)+H21) -> -62930.516 | I24: =IF(I19="","",(-I22)+I21) -> 177784.73 | J24: =IF(J19="","",(-J22)+J21) -> 180876.29 | K24: =IF(K19="","",(-K22)+K21) -> 183948.72 | L24: =IF(L19="","",(-L22)+L21) -> 187000.43 | M24: =IF(M19="","",(-M22)+M21) -> 190029.8 | ... U24: =IF(U19="","",(-U22)+U21)
B25: LP Equity Multiple | D25: =IF(GP_Only?,"NA",D21/D22) -> 2.4080514
B27: Sponsor Returns
B28: Total Sponsor Distributions | D28: =SUM(F28:U28) -> 1061225.1 | F28: =IF(F19="","",F56+F72+F87+F94) -> 0 | G28: =IF(G19="","",G56+G72+G87+G94) -> 0 | H28: =IF(H19="","",H56+H72+H87+H94) -> 0 | I28: =IF(I19="","",I56+I72+I87+I94) -> 19753.859 | J28: =IF(J19="","",J56+J72+J87+J94) -> 20097.366 | K28: =IF(K19="","",K56+K72+K87+K94) -> 20438.747 | L28: =IF(L19="","",L56+L72+L87+L94) -> 20777.826 | M28: =IF(M19="","",M56+M72+M87+M94) -> 21114.422 | ... U28: =IF(U19="","",U56+U72+U87+U94)
B29: Total Sponsor Fees | D29: =SUM(F29:U29) -> 0 | F29: =IF(F19="","",SUM(F38:F39)) -> 0 | G29: =IF(G19="","",SUM(G38:G39)) -> 0 | H29: =IF(H19="","",SUM(H38:H39)) -> 0 | I29: =IF(I19="","",SUM(I38:I39)) -> 0 | J29: =IF(J19="","",SUM(J38:J39)) -> 0 | K29: =IF(K19="","",SUM(K38:K39)) -> 0 | L29: =IF(L19="","",SUM(L38:L39)) -> 0 | M29: =IF(M19="","",SUM(M38:M39)) -> 0 | ... U29: =IF(U19="","",SUM(U38:U39))
B30: Total Sponsor Contributions | D30: =SUM(F30:U30) -> 300360.13 | F30: =IF(F19="","",-(MIN(F40,0)+F49)) -> 265712.5 | G30: =IF(G19="","",-(MIN(G40,0)+G49)) -> 27655.35 | H30: =IF(H19="","",-(MIN(H40,0)+H49)) -> 6992.2795 | I30: =IF(I19="","",-(MIN(I40,0)+I49)) -> 0 | J30: =IF(J19="","",-(MIN(J40,0)+J49)) -> 0 | K30: =IF(K19="","",-(MIN(K40,0)+K49)) -> 0 | L30: =IF(L19="","",-(MIN(L40,0)+L49)) -> 0 | M30: =IF(M19="","",-(MIN(M40,0)+M49)) -> 0 | ... U30: =IF(U19="","",-(MIN(U40,0)+U49))
B31: Total Sponsor Profit | D31: =+D28+D29-D30 -> 760864.94
B32: Sponsor IRR | D32: =IRR(F32:U32) -> 0.14827582 | F32: =IF(F19="","",(-F30)+F28+F29) -> -265712.5 | G32: =IF(G19="","",(-G30)+G28+G29) -> -27655.35 | H32: =IF(H19="","",(-H30)+H28+H29) -> -6992.2795 | I32: =IF(I19="","",(-I30)+I28+I29) -> 19753.859 | J32: =IF(J19="","",(-J30)+J28+J29) -> 20097.366 | K32: =IF(K19="","",(-K30)+K28+K29) -> 20438.747 | L32: =IF(L19="","",(-L30)+L28+L29) -> 20777.826 | M32: =IF(M19="","",(-M30)+M28+M29) -> 21114.422 | ... U32: =IF(U19="","",(-U30)+U28+U29)
B33: Sponsor Equity Multiple | D33: =SUMIF(F32:U32,">0")/-SUMIF(F32:U32,"<0") -> 3.5331756
B35: Net Cash Flow For Distribution | F35: Year 0 | G35: =G19 -> 1 | H35: =H19 -> 2 | I35: =I19 -> 3 | J35: =J19 -> 4 | K35: =K19 -> 5 | L35: =L19 -> 6 | M35: =M19 -> 7 | N35: =N19 -> 8 | ... U35: =U19
E36: Year Ending | F36: =EOMONTH(G36,-12) -> 42369 | G36: =IF(G35="","",'Property Returns'!D4) -> 42735 | H36: =IF(H35="","",'Property Returns'!E4) -> 43100 | I36: =IF(I35="","",'Property Returns'!F4) -> 43465 | J36: =IF(J35="","",'Property Returns'!G4) -> 43830 | K36: =IF(K35="","",'Property Returns'!H4) -> 44196 | L36: =IF(L35="","",'Property Returns'!I4) -> 44561 | M36: =IF(M35="","",'Property Returns'!J4) -> 44926 | N36: =IF(N35="","",'Property Returns'!K4) -> 45291 | ... U36: =IF(U35="","",'Property Returns'!R4)
B37: Net Levered Before Tax Cash Flow | F37: =-Initial_Equity -> -2657125 | G37: =IF(G19="","",'Property Returns'!D34+(G19=Analysis_Period)*'Property Returns'!D31) -> -276553.5 | H37: =IF(H19="","",'Property Returns'!E34+(H19=Analysis_Period)*'Property Returns'!E31) -> -69922.795 | I37: =IF(I19="","",'Property Returns'!F34+(I19=Analysis_Period)*'Property Returns'!F31) -> 197538.59 | J37: =IF(J19="","",'Property Returns'!G34+(J19=Analysis_Period)*'Property Returns'!G31) -> 200973.66 | K37: =IF(K19="","",'Property Returns'!H34+(K19=Analysis_Period)*'Property Returns'!H31) -> 204387.47 | L37: =IF(L19="","",'Property Returns'!I34+(L19=Analysis_Period)*'Property Returns'!I31) -> 207778.26 | M37: =IF(M19="","",'Property Returns'!J34+(M19=Analysis_Period)*'Property Returns'!J31) -> 211144.22 | N37: =IF(N19="","",'Property Returns'!K34+(N19=Analysis_Period)*'Property Returns'!K31) -> 214483.47 | ... U37: =IF(U19="","",'Property Returns'!R34+(U19=Analysis_Period)*'Property Returns'!R31)
B38: Asset Management Fees | F38: 0 | G38: 0 | H38: 0 | I38: 0 | J38: 0 | K38: 0 | L38: 0 | M38: 0 | N38: 0 | O38: 0 | P38: 0
B39: Acquisition/Disposition Fees | F39: 0 | G39: 0 | H39: 0 | I39: 0 | J39: 0 | K39: 0 | L39: 0 | M39: 0 | N39: 0 | O39: 0 | P39: 0
B40: Adjusted Levered Before Tax Cash Flow | F40: =IF(F35="","",F37-F38-F39) -> -2657125 | G40: =IF(G35="","",G37-G38-G39) -> -276553.5 | H40: =IF(H35="","",H37-H38-H39) -> -69922.795 | I40: =IF(I35="","",I37-I38-I39) -> 197538.59 | J40: =IF(J35="","",J37-J38-J39) -> 200973.66 | K40: =IF(K35="","",K37-K38-K39) -> 204387.47 | L40: =IF(L35="","",L37-L38-L39) -> 207778.26 | M40: =IF(M35="","",M37-M38-M39) -> 211144.22 | ... U40: =IF(U35="","",U37-U38-U39)
B41: Levered IRR | F41: =IRR(F40:U40) -> 0.10915008
B42: Equity Multiple | F42: =SUMIF(F40:U40,">0")/-SUMIF(F40:U40,"<0") -> 2.5205638
B44: Return of Capital & Hurdle 1 (Preferred Return)
B45: Return Threshold - Up to: | C45: =E14 -> 0.08
B46: Beginning Balance (LP Capital Account) | F46: =IF(F35="","",E51) -> 0 | G46: =IF(G35="","",F51) -> 2391412.5 | H46: =IF(H35="","",G51) -> 2831623.6 | I46: =IF(I35="","",H51) -> 3121084.1 | J46: =IF(J35="","",I51) -> 3192986 | K46: =IF(K35="","",J51) -> 3267548.6 | L46: =IF(L35="","",K51) -> 3345003.8 | M46: =IF(M35="","",L51) -> 3425603.7 | ... U46: =IF(U35="","",T51)
B47: LP Return of Capital | F47: =IF(ROUND(SUM(G47:U47),0)=ROUND(SUM(F49:U49),0),"All Capital Returned","Capital Not Returned") -> All Capital Returned | G47: =IF(G35="","",G53-G48) -> -191313 | H47: =IF(H35="","",H53-H48) -> -226529.89 | I47: =IF(I35="","",I53-I48) -> -71901.99 | J47: =IF(J35="","",J53-J48) -> -74562.591 | K47: =IF(K35="","",K53-K48) -> -77455.17 | L47: =IF(L35="","",L53-L48) -> -80599.871 | M47: =IF(M35="","",M53-M48) -> -84018.498 | N47: =IF(N35="","",N53-N48) -> -87734.653 | ... U47: =IF(U35="","",U53-U48)
B48: Req'd Return by LP to hit Hurdle 1 | F48: =IF(F46="","",IF($D$4="Equity Multiple",E49*$C45-E49,F46*Preferred_Return)) -> 0 | G48: =IF(G46="","",IF($D$4="Equity Multiple",F49*$C45-F49,G46*Preferred_Return)) -> 191313 | H48: =IF(H46="","",IF($D$4="Equity Multiple",G49*$C45-G49,H46*Preferred_Return)) -> 226529.89 | I48: =IF(I46="","",IF($D$4="Equity Multiple",H49*$C45-H49,I46*Preferred_Return)) -> 249686.72 | J48: =IF(J46="","",IF($D$4="Equity Multiple",I49*$C45-I49,J46*Preferred_Return)) -> 255438.88 | K48: =IF(K46="","",IF($D$4="Equity Multiple",J49*$C45-J49,K46*Preferred_Return)) -> 261403.89 | L48: =IF(L46="","",IF($D$4="Equity Multiple",K49*$C45-K49,L46*Preferred_Return)) -> 267600.3 | M48: =IF(M46="","",IF($D$4="Equity Multiple",L49*$C45-L49,M46*Preferred_Return)) -> 274048.29 | ... U48: =IF(U46="","",IF($D$4="Equity Multiple",T49*$C45-T49,U46*Preferred_Return))
...

Sheet Debt
B2: Permanent Financing
D3: 1 | E3: =IF(OR(D3="",D3=Analysis_Period),"",D3+1) -> 2 | F3: =IF(OR(E3="",E3=Analysis_Period),"",E3+1) -> 3 | G3: =IF(OR(F3="",F3=Analysis_Period),"",F3+1) -> 4 | H3: =IF(OR(G3="",G3=Analysis_Period),"",G3+1) -> 5 | I3: =IF(OR(H3="",H3=Analysis_Period),"",H3+1) -> 6 | J3: =IF(OR(I3="",I3=Analysis_Period),"",I3+1) -> 7 | K3: =IF(OR(J3="",J3=Analysis_Period),"",J3+1) -> 8 | L3: =IF(OR(K3="",K3=Analysis_Period),"",K3+1) -> 9 | ... T3: =IF(OR(S3="",S3=Analysis_Period),"",S3+1)
